Workbook

Sheet RSA
B2: RSA encryption, step by step
B3: Edit the three amber cells. All calculations use ordinary formulas, with no macros.
B5: Prime p | C5: 13 | E5: Choose two different primes below 100.
B6: Prime q | C6: 41 | E6: Their product n must exceed every message byte.
B7: Message | C7: Hello world! | E7: Up to 16 printable ASCII characters (space through ~). No accents or emoji.
B10: Primes valid? | C10: =AND(COUNTIFS('Key steps'!$N$9:$N$33,C5)=1,COUNTIFS('Key steps'!$N$9:$N$33,C6)=1,C5<>C6) -> TRUE | E10: Both inputs must be distinct primes from the dropdown.
B11: Message valid? | C11: =AND(LEN(C7)>=1,LEN(C7)<=16,MIN(D42:D57)>=32,MAX(D42:D57)<=126) -> TRUE
B12: Input status | C12: =IF(NOT(C10),"Choose distinct primes",IF(NOT(C11),"Use 1–16 ASCII chars",IF(C16<=MAX(D42:D57),"Choose larger primes","Ready"))) -> Ready | E12: If n is too small, the byte cannot be recovered uniquely.
B15: 1. Make the keys | C15: Calculated value
B16: Modulus n | C16: =IF(C10,C5*C6,"") -> 533 | E16: n = p × q. MOD(x, n) means the remainder after dividing x by n.
B17: Totient φ(n) | C17: =IF(C10,(C5-1)*(C6-1),"") -> 480 | E17: φ(n) = (p − 1) × (q − 1), because p and q are distinct primes.
B18: Public exponent e | C18: =IF(C10,MIN('Key steps'!D9:D106),"") -> 7 | E18: Choose the smallest e > 1 with e < n and GCD(e, φ) = 1. See "Key steps" tab.
B19: Private exponent d | C19: =IF(C10,SUM('Key steps'!J9:J107),"") -> 343 | E19: Find d so e × d = 1 + k × φ. See the "Key steps" tab for the integer search.
B20: e × d | C20: =IF(C10,C18*C19,"") -> 2401 | E20: The exponents multiply to one more than a multiple of φ.
B21: MOD(e × d, φ) | C21: =IF(C10,MOD(C20,C17),"") -> 1 | E21: This must equal 1: d is the modular inverse of e.
B23: Public key (e, n) | C23: =IF(C10,"("&C18&", "&C16&")","") -> (7, 533) | E23: Share this pair. Encrypt each byte m as c = m^e mod n.
B24: Private key (d, n) | C24: =IF(C10,"("&C19&", "&C16&")","") -> (343, 533) | E24: Keep d secret in real use. Decrypt as m = c^d mod n.
B27: 2. Message results
B28: Original bytes (hex) | C28: =E42&IF(LEN(E43)=0,""," "&E43)&IF(LEN(E44)=0,""," "&E44)&IF(LEN(E45)=0,""," "&E45)&IF(LEN(E46)=0,""," "&E46)&IF(LEN(E47)=0,""," "&E47)&IF(LEN(E48)=0,""," "&E48)&IF(LEN(E49)=0,""," "&E49)&IF(LEN(E50)=0,""," "&E50)&IF(LEN(E51)=0,""," "&E51)&IF(LEN(E52)=0,""," "&E52)&IF(LEN(E53)=0,""," "&E53)&IF(LEN(E54)=0,""," "&E54)&IF(LEN(E55)=0,""," "&E55)&IF(LEN(E56)=0,""," "&E56)&IF(LEN(E57)=0,""," "&E57) -> 48 65 6C 6C 6F 20 77 6F 72 6C 64 21
B29: Encrypted bytes (hex) | C29: =I42&IF(LEN(I43)=0,""," "&I43)&IF(LEN(I44)=0,""," "&I44)&IF(LEN(I45)=0,""," "&I45)&IF(LEN(I46)=0,""," "&I46)&IF(LEN(I47)=0,""," "&I47)&IF(LEN(I48)=0,""," "&I48)&IF(LEN(I49)=0,""," "&I49)&IF(LEN(I50)=0,""," "&I50)&IF(LEN(I51)=0,""," "&I51)&IF(LEN(I52)=0,""," "&I52)&IF(LEN(I53)=0,""," "&I53)&IF(LEN(I54)=0,""," "&I54)&IF(LEN(I55)=0,""," "&I55)&IF(LEN(I56)=0,""," "&I56)&IF(LEN(I57)=0,""," "&I57) -> 01 DA 00 99 00 D4 00 D4 00 13 01 F5 00 B4 00 13 01 28 00 D4 02 11 00 A2
B31: Decrypted bytes (hex) | C31: =K42&IF(LEN(K43)=0,""," "&K43)&IF(LEN(K44)=0,""," "&K44)&IF(LEN(K45)=0,""," "&K45)&IF(LEN(K46)=0,""," "&K46)&IF(LEN(K47)=0,""," "&K47)&IF(LEN(K48)=0,""," "&K48)&IF(LEN(K49)=0,""," "&K49)&IF(LEN(K50)=0,""," "&K50)&IF(LEN(K51)=0,""," "&K51)&IF(LEN(K52)=0,""," "&K52)&IF(LEN(K53)=0,""," "&K53)&IF(LEN(K54)=0,""," "&K54)&IF(LEN(K55)=0,""," "&K55)&IF(LEN(K56)=0,""," "&K56)&IF(LEN(K57)=0,""," "&K57) -> 48 65 6C 6C 6F 20 77 6F 72 6C 64 21
B32: Decrypted message | C32: =L42&IF(LEN(L43)=0,"",L43)&IF(LEN(L44)=0,"",L44)&IF(LEN(L45)=0,"",L45)&IF(LEN(L46)=0,"",L46)&IF(LEN(L47)=0,"",L47)&IF(LEN(L48)=0,"",L48)&IF(LEN(L49)=0,"",L49)&IF(LEN(L50)=0,"",L50)&IF(LEN(L51)=0,"",L51)&IF(LEN(L52)=0,"",L52)&IF(LEN(L53)=0,"",L53)&IF(LEN(L54)=0,"",L54)&IF(LEN(L55)=0,"",L55)&IF(LEN(L56)=0,"",L56)&IF(LEN(L57)=0,"",L57) -> Hello world!
B33: Exact match? | C33: =IF(C12="Ready",IF(EXACT(C7,C32),"Yes","NO — mismatch"),"Fix inputs first") -> Yes
B35: Hex uses two digits per byte. Each encrypted block below is two bytes, high byte first (big-endian).
B36: Two-byte storage is fixed for clarity, even when one byte would be enough. A blank row is not a zero byte.
B38: Message encryption / decryption byte by byte
F39: ="e = " &$C$18 -> e = 7 | J39: ="d = "&$C$19 -> d = 343
F40: ="n = " &$C$16 -> n = 533 | J40: ="n = " &$C$16 -> n = 533
B41: Position | C41: Character | D41: Byte m | E41: m hex | F41: Cipher c c = m^e mod n | G41: High byte | H41: Low byte | I41: c bytes hex | J41: Recovered m m = c^d mod n | K41: m hex | L41: Character
B42: 1 | C42: =IF(B42<=LEN($C$7),MID($C$7,B42,1),"") -> H | D42: =IF(LEN(C42)=0,"",_xlfn.UNICODE(C42&"x")) -> 72 | E42: =IF(LEN(C42)=0,"",IF(AND(D42>=32,D42<=126),DEC2HEX(D42,2),"Not ASCII")) -> 48 | F42: =IF(OR($C$12<>"Ready",LEN(C42)=0),"",'Power steps'!G23) -> 474 | G42: =IF(LEN(F42)=0,"",INT(F42/256)) -> 1 | H42: =IF(LEN(F42)=0,"",MOD(F42,256)) -> 218 | I42: =IF(LEN(F42)=0,"",DEC2HEX(G42,2)&" "&DEC2HEX(H42,2)) -> 01 DA | J42: =IF(LEN(F42)=0,"",'Power steps'!O23) -> 72 | K42: =IF(LEN(J42)=0,"",DEC2HEX(J42,2)) -> 48 | L42: =IF(LEN(J42)=0,"",CHAR(J42)) -> H
B43: 2 | C43: =IF(B43<=LEN($C$7),MID($C$7,B43,1),"") -> e | D43: =IF(LEN(C43)=0,"",_xlfn.UNICODE(C43&"x")) -> 101 | E43: =IF(LEN(C43)=0,"",IF(AND(D43>=32,D43<=126),DEC2HEX(D43,2),"Not ASCII")) -> 65 | F43: =IF(OR($C$12<>"Ready",LEN(C43)=0),"",'Power steps'!G41) -> 153 | G43: =IF(LEN(F43)=0,"",INT(F43/256)) -> 0 | H43: =IF(LEN(F43)=0,"",MOD(F43,256)) -> 153 | I43: =IF(LEN(F43)=0,"",DEC2HEX(G43,2)&" "&DEC2HEX(H43,2)) -> 00 99 | J43: =IF(LEN(F43)=0,"",'Power steps'!O41) -> 101 | K43: =IF(LEN(J43)=0,"",DEC2HEX(J43,2)) -> 65 | L43: =IF(LEN(J43)=0,"",CHAR(J43)) -> e
B44: 3 | C44: =IF(B44<=LEN($C$7),MID($C$7,B44,1),"") -> l | D44: =IF(LEN(C44)=0,"",_xlfn.UNICODE(C44&"x")) -> 108 | E44: =IF(LEN(C44)=0,"",IF(AND(D44>=32,D44<=126),DEC2HEX(D44,2),"Not ASCII")) -> 6C | F44: =IF(OR($C$12<>"Ready",LEN(C44)=0),"",'Power steps'!G59) -> 212 | G44: =IF(LEN(F44)=0,"",INT(F44/256)) -> 0 | H44: =IF(LEN(F44)=0,"",MOD(F44,256)) -> 212 | I44: =IF(LEN(F44)=0,"",DEC2HEX(G44,2)&" "&DEC2HEX(H44,2)) -> 00 D4 | J44: =IF(LEN(F44)=0,"",'Power steps'!O59) -> 108 | K44: =IF(LEN(J44)=0,"",DEC2HEX(J44,2)) -> 6C | L44: =IF(LEN(J44)=0,"",CHAR(J44)) -> l
B45: 4 | C45: =IF(B45<=LEN($C$7),MID($C$7,B45,1),"") -> l | D45: =IF(LEN(C45)=0,"",_xlfn.UNICODE(C45&"x")) -> 108 | E45: =IF(LEN(C45)=0,"",IF(AND(D45>=32,D45<=126),DEC2HEX(D45,2),"Not ASCII")) -> 6C | F45: =IF(OR($C$12<>"Ready",LEN(C45)=0),"",'Power steps'!G77) -> 212 | G45: =IF(LEN(F45)=0,"",INT(F45/256)) -> 0 | H45: =IF(LEN(F45)=0,"",MOD(F45,256)) -> 212 | I45: =IF(LEN(F45)=0,"",DEC2HEX(G45,2)&" "&DEC2HEX(H45,2)) -> 00 D4 | J45: =IF(LEN(F45)=0,"",'Power steps'!O77) -> 108 | K45: =IF(LEN(J45)=0,"",DEC2HEX(J45,2)) -> 6C | L45: =IF(LEN(J45)=0,"",CHAR(J45)) -> l
B46: 5 | C46: =IF(B46<=LEN($C$7),MID($C$7,B46,1),"") -> o | D46: =IF(LEN(C46)=0,"",_xlfn.UNICODE(C46&"x")) -> 111 | E46: =IF(LEN(C46)=0,"",IF(AND(D46>=32,D46<=126),DEC2HEX(D46,2),"Not ASCII")) -> 6F | F46: =IF(OR($C$12<>"Ready",LEN(C46)=0),"",'Power steps'!G95) -> 19 | G46: =IF(LEN(F46)=0,"",INT(F46/256)) -> 0 | H46: =IF(LEN(F46)=0,"",MOD(F46,256)) -> 19 | I46: =IF(LEN(F46)=0,"",DEC2HEX(G46,2)&" "&DEC2HEX(H46,2)) -> 00 13 | J46: =IF(LEN(F46)=0,"",'Power steps'!O95) -> 111 | K46: =IF(LEN(J46)=0,"",DEC2HEX(J46,2)) -> 6F | L46: =IF(LEN(J46)=0,"",CHAR(J46)) -> o
B47: 6 | C47: =IF(B47<=LEN($C$7),MID($C$7,B47,1),"") | D47: =IF(LEN(C47)=0,"",_xlfn.UNICODE(C47&"x")) -> 32 | E47: =IF(LEN(C47)=0,"",IF(AND(D47>=32,D47<=126),DEC2HEX(D47,2),"Not ASCII")) -> 20 | F47: =IF(OR($C$12<>"Ready",LEN(C47)=0),"",'Power steps'!G113) -> 501 | G47: =IF(LEN(F47)=0,"",INT(F47/256)) -> 1 | H47: =IF(LEN(F47)=0,"",MOD(F47,256)) -> 245 | I47: =IF(LEN(F47)=0,"",DEC2HEX(G47,2)&" "&DEC2HEX(H47,2)) -> 01 F5 | J47: =IF(LEN(F47)=0,"",'Power steps'!O113) -> 32 | K47: =IF(LEN(J47)=0,"",DEC2HEX(J47,2)) -> 20 | L47: =IF(LEN(J47)=0,"",CHAR(J47))
B48: 7 | C48: =IF(B48<=LEN($C$7),MID($C$7,B48,1),"") -> w | D48: =IF(LEN(C48)=0,"",_xlfn.UNICODE(C48&"x")) -> 119 | E48: =IF(LEN(C48)=0,"",IF(AND(D48>=32,D48<=126),DEC2HEX(D48,2),"Not ASCII")) -> 77 | F48: =IF(OR($C$12<>"Ready",LEN(C48)=0),"",'Power steps'!G131) -> 180 | G48: =IF(LEN(F48)=0,"",INT(F48/256)) -> 0 | H48: =IF(LEN(F48)=0,"",MOD(F48,256)) -> 180 | I48: =IF(LEN(F48)=0,"",DEC2HEX(G48,2)&" "&DEC2HEX(H48,2)) -> 00 B4 | J48: =IF(LEN(F48)=0,"",'Power steps'!O131) -> 119 | K48: =IF(LEN(J48)=0,"",DEC2HEX(J48,2)) -> 77 | L48: =IF(LEN(J48)=0,"",CHAR(J48)) -> w
B49: 8 | C49: =IF(B49<=LEN($C$7),MID($C$7,B49,1),"") -> o | D49: =IF(LEN(C49)=0,"",_xlfn.UNICODE(C49&"x")) -> 111 | E49: =IF(LEN(C49)=0,"",IF(AND(D49>=32,D49<=126),DEC2HEX(D49,2),"Not ASCII")) -> 6F | F49: =IF(OR($C$12<>"Ready",LEN(C49)=0),"",'Power steps'!G149) -> 19 | G49: =IF(LEN(F49)=0,"",INT(F49/256)) -> 0 | H49: =IF(LEN(F49)=0,"",MOD(F49,256)) -> 19 | I49: =IF(LEN(F49)=0,"",DEC2HEX(G49,2)&" "&DEC2HEX(H49,2)) -> 00 13 | J49: =IF(LEN(F49)=0,"",'Power steps'!O149) -> 111 | K49: =IF(LEN(J49)=0,"",DEC2HEX(J49,2)) -> 6F | L49: =IF(LEN(J49)=0,"",CHAR(J49)) -> o
B50: 9 | C50: =IF(B50<=LEN($C$7),MID($C$7,B50,1),"") -> r | D50: =IF(LEN(C50)=0,"",_xlfn.UNICODE(C50&"x")) -> 114 | E50: =IF(LEN(C50)=0,"",IF(AND(D50>=32,D50<=126),DEC2HEX(D50,2),"Not ASCII")) -> 72 | F50: =IF(OR($C$12<>"Ready",LEN(C50)=0),"",'Power steps'!G167) -> 296 | G50: =IF(LEN(F50)=0,"",INT(F50/256)) -> 1 | H50: =IF(LEN(F50)=0,"",MOD(F50,256)) -> 40 | I50: =IF(LEN(F50)=0,"",DEC2HEX(G50,2)&" "&DEC2HEX(H50,2)) -> 01 28 | J50: =IF(LEN(F50)=0,"",'Power steps'!O167) -> 114 | K50: =IF(LEN(J50)=0,"",DEC2HEX(J50,2)) -> 72 | L50: =IF(LEN(J50)=0,"",CHAR(J50)) -> r
B51: 10 | C51: =IF(B51<=LEN($C$7),MID($C$7,B51,1),"") -> l | D51: =IF(LEN(C51)=0,"",_xlfn.UNICODE(C51&"x")) -> 108 | E51: =IF(LEN(C51)=0,"",IF(AND(D51>=32,D51<=126),DEC2HEX(D51,2),"Not ASCII")) -> 6C | F51: =IF(OR($C$12<>"Ready",LEN(C51)=0),"",'Power steps'!G185) -> 212 | G51: =IF(LEN(F51)=0,"",INT(F51/256)) -> 0 | H51: =IF(LEN(F51)=0,"",MOD(F51,256)) -> 212 | I51: =IF(LEN(F51)=0,"",DEC2HEX(G51,2)&" "&DEC2HEX(H51,2)) -> 00 D4 | J51: =IF(LEN(F51)=0,"",'Power steps'!O185) -> 108 | K51: =IF(LEN(J51)=0,"",DEC2HEX(J51,2)) -> 6C | L51: =IF(LEN(J51)=0,"",CHAR(J51)) -> l
B52: 11 | C52: =IF(B52<=LEN($C$7),MID($C$7,B52,1),"") -> d | D52: =IF(LEN(C52)=0,"",_xlfn.UNICODE(C52&"x")) -> 100 | E52: =IF(LEN(C52)=0,"",IF(AND(D52>=32,D52<=126),DEC2HEX(D52,2),"Not ASCII")) -> 64 | F52: =IF(OR($C$12<>"Ready",LEN(C52)=0),"",'Power steps'!G203) -> 529 | G52: =IF(LEN(F52)=0,"",INT(F52/256)) -> 2 | H52: =IF(LEN(F52)=0,"",MOD(F52,256)) -> 17 | I52: =IF(LEN(F52)=0,"",DEC2HEX(G52,2)&" "&DEC2HEX(H52,2)) -> 02 11 | J52: =IF(LEN(F52)=0,"",'Power steps'!O203) -> 100 | K52: =IF(LEN(J52)=0,"",DEC2HEX(J52,2)) -> 64 | L52: =IF(LEN(J52)=0,"",CHAR(J52)) -> d
...

Sheet Key steps
A2: How the exponents are selected
A4: Left: test e = 2 to 99. GCD is the greatest common divisor. A value of 1 means the numbers are coprime.
A5: Right: test k = 0 to 98 in d = (1 + k × φ) / e. Exactly one k below e makes d an integer.
A6: The minimum valid e is selected. The search includes a solution for every pair of distinct primes below 100.
A8: Candidate e | B8: GCD(e, φ) | C8: Usable? | D8: Valid e | F8: Candidate k | G8: 1 + k × φ | H8: ÷ e | I8: Remainder ÷ e | J8: Integer d | N8: Primes < 100
A9: 2 | B9: =IF(RSA!$C$10,GCD(A9,RSA!$C$17),"") -> 2 | C9: =IF(RSA!$C$10,AND(A9<RSA!$C$16,B9=1),FALSE) -> FALSE | D9: =IF(C9,A9,"") | F9: 0 | G9: =IF(RSA!$C$10,1+F9*RSA!$C$17,"") -> 1 | H9: =IF(RSA!$C$10,G9/RSA!$C$18,"") -> 0.14285714 | I9: =IF(RSA!$C$10,MOD(G9,RSA!$C$18),"") -> 1 | J9: =IF(RSA!$C$10,IF(AND(F9<RSA!$C$18,I9=0),H9,""),"") | N9: 2
A10: 3 | B10: =IF(RSA!$C$10,GCD(A10,RSA!$C$17),"") -> 3 | C10: =IF(RSA!$C$10,AND(A10<RSA!$C$16,B10=1),FALSE) -> FALSE | D10: =IF(C10,A10,"") | F10: 1 | G10: =IF(RSA!$C$10,1+F10*RSA!$C$17,"") -> 481 | H10: =IF(RSA!$C$10,G10/RSA!$C$18,"") -> 68.714286 | I10: =IF(RSA!$C$10,MOD(G10,RSA!$C$18),"") -> 5 | J10: =IF(RSA!$C$10,IF(AND(F10<RSA!$C$18,I10=0),H10,""),"") | N10: 3
A11: 4 | B11: =IF(RSA!$C$10,GCD(A11,RSA!$C$17),"") -> 4 | C11: =IF(RSA!$C$10,AND(A11<RSA!$C$16,B11=1),FALSE) -> FALSE | D11: =IF(C11,A11,"") | F11: 2 | G11: =IF(RSA!$C$10,1+F11*RSA!$C$17,"") -> 961 | H11: =IF(RSA!$C$10,G11/RSA!$C$18,"") -> 137.28571 | I11: =IF(RSA!$C$10,MOD(G11,RSA!$C$18),"") -> 2 | J11: =IF(RSA!$C$10,IF(AND(F11<RSA!$C$18,I11=0),H11,""),"") | N11: 5
A12: 5 | B12: =IF(RSA!$C$10,GCD(A12,RSA!$C$17),"") -> 5 | C12: =IF(RSA!$C$10,AND(A12<RSA!$C$16,B12=1),FALSE) -> FALSE | D12: =IF(C12,A12,"") | F12: 3 | G12: =IF(RSA!$C$10,1+F12*RSA!$C$17,"") -> 1441 | H12: =IF(RSA!$C$10,G12/RSA!$C$18,"") -> 205.85714 | I12: =IF(RSA!$C$10,MOD(G12,RSA!$C$18),"") -> 6 | J12: =IF(RSA!$C$10,IF(AND(F12<RSA!$C$18,I12=0),H12,""),"") | N12: 7
A13: 6 | B13: =IF(RSA!$C$10,GCD(A13,RSA!$C$17),"") -> 6 | C13: =IF(RSA!$C$10,AND(A13<RSA!$C$16,B13=1),FALSE) -> FALSE | D13: =IF(C13,A13,"") | F13: 4 | G13: =IF(RSA!$C$10,1+F13*RSA!$C$17,"") -> 1921 | H13: =IF(RSA!$C$10,G13/RSA!$C$18,"") -> 274.42857 | I13: =IF(RSA!$C$10,MOD(G13,RSA!$C$18),"") -> 3 | J13: =IF(RSA!$C$10,IF(AND(F13<RSA!$C$18,I13=0),H13,""),"") | N13: 11
A14: 7 | B14: =IF(RSA!$C$10,GCD(A14,RSA!$C$17),"") -> 1 | C14: =IF(RSA!$C$10,AND(A14<RSA!$C$16,B14=1),FALSE) -> TRUE | D14: =IF(C14,A14,"") -> 7 | F14: 5 | G14: =IF(RSA!$C$10,1+F14*RSA!$C$17,"") -> 2401 | H14: =IF(RSA!$C$10,G14/RSA!$C$18,"") -> 343 | I14: =IF(RSA!$C$10,MOD(G14,RSA!$C$18),"") -> 0 | J14: =IF(RSA!$C$10,IF(AND(F14<RSA!$C$18,I14=0),H14,""),"") -> 343 | N14: 13
A15: 8 | B15: =IF(RSA!$C$10,GCD(A15,RSA!$C$17),"") -> 8 | C15: =IF(RSA!$C$10,AND(A15<RSA!$C$16,B15=1),FALSE) -> FALSE | D15: =IF(C15,A15,"") | F15: 6 | G15: =IF(RSA!$C$10,1+F15*RSA!$C$17,"") -> 2881 | H15: =IF(RSA!$C$10,G15/RSA!$C$18,"") -> 411.57143 | I15: =IF(RSA!$C$10,MOD(G15,RSA!$C$18),"") -> 4 | J15: =IF(RSA!$C$10,IF(AND(F15<RSA!$C$18,I15=0),H15,""),"") | N15: 17
A16: 9 | B16: =IF(RSA!$C$10,GCD(A16,RSA!$C$17),"") -> 3 | C16: =IF(RSA!$C$10,AND(A16<RSA!$C$16,B16=1),FALSE) -> FALSE | D16: =IF(C16,A16,"") | F16: 7 | G16: =IF(RSA!$C$10,1+F16*RSA!$C$17,"") -> 3361 | H16: =IF(RSA!$C$10,G16/RSA!$C$18,"") -> 480.14286 | I16: =IF(RSA!$C$10,MOD(G16,RSA!$C$18),"") -> 1 | J16: =IF(RSA!$C$10,IF(AND(F16<RSA!$C$18,I16=0),H16,""),"") | N16: 19
A17: 10 | B17: =IF(RSA!$C$10,GCD(A17,RSA!$C$17),"") -> 10 | C17: =IF(RSA!$C$10,AND(A17<RSA!$C$16,B17=1),FALSE) -> FALSE | D17: =IF(C17,A17,"") | F17: 8 | G17: =IF(RSA!$C$10,1+F17*RSA!$C$17,"") -> 3841 | H17: =IF(RSA!$C$10,G17/RSA!$C$18,"") -> 548.71429 | I17: =IF(RSA!$C$10,MOD(G17,RSA!$C$18),"") -> 5 | J17: =IF(RSA!$C$10,IF(AND(F17<RSA!$C$18,I17=0),H17,""),"") | N17: 23
A18: 11 | B18: =IF(RSA!$C$10,GCD(A18,RSA!$C$17),"") -> 1 | C18: =IF(RSA!$C$10,AND(A18<RSA!$C$16,B18=1),FALSE) -> TRUE | D18: =IF(C18,A18,"") -> 11 | F18: 9 | G18: =IF(RSA!$C$10,1+F18*RSA!$C$17,"") -> 4321 | H18: =IF(RSA!$C$10,G18/RSA!$C$18,"") -> 617.28571 | I18: =IF(RSA!$C$10,MOD(G18,RSA!$C$18),"") -> 2 | J18: =IF(RSA!$C$10,IF(AND(F18<RSA!$C$18,I18=0),H18,""),"") | N18: 29
A19: 12 | B19: =IF(RSA!$C$10,GCD(A19,RSA!$C$17),"") -> 12 | C19: =IF(RSA!$C$10,AND(A19<RSA!$C$16,B19=1),FALSE) -> FALSE | D19: =IF(C19,A19,"") | F19: 10 | G19: =IF(RSA!$C$10,1+F19*RSA!$C$17,"") -> 4801 | H19: =IF(RSA!$C$10,G19/RSA!$C$18,"") -> 685.85714 | I19: =IF(RSA!$C$10,MOD(G19,RSA!$C$18),"") -> 6 | J19: =IF(RSA!$C$10,IF(AND(F19<RSA!$C$18,I19=0),H19,""),"") | N19: 31
A20: 13 | B20: =IF(RSA!$C$10,GCD(A20,RSA!$C$17),"") -> 1 | C20: =IF(RSA!$C$10,AND(A20<RSA!$C$16,B20=1),FALSE) -> TRUE | D20: =IF(C20,A20,"") -> 13 | F20: 11 | G20: =IF(RSA!$C$10,1+F20*RSA!$C$17,"") -> 5281 | H20: =IF(RSA!$C$10,G20/RSA!$C$18,"") -> 754.42857 | I20: =IF(RSA!$C$10,MOD(G20,RSA!$C$18),"") -> 3 | J20: =IF(RSA!$C$10,IF(AND(F20<RSA!$C$18,I20=0),H20,""),"") | N20: 37
... A33: 26 | B33: =IF(RSA!$C$10,GCD(A33,RSA!$C$17),"") -> 2 | C33: =IF(RSA!$C$10,AND(A33<RSA!$C$16,B33=1),FALSE) -> FALSE | D33: =IF(C33,A33,"") | F33: 24 | G33: =IF(RSA!$C$10,1+F33*RSA!$C$17,"") -> 11521 | H33: =IF(RSA!$C$10,G33/RSA!$C$18,"") -> 1645.8571 | I33: =IF(RSA!$C$10,MOD(G33,RSA!$C$18),"") -> 6 | J33: =IF(RSA!$C$10,IF(AND(F33<RSA!$C$18,I33=0),H33,""),"") | N33: 97
A34: 27 | B34: =IF(RSA!$C$10,GCD(A34,RSA!$C$17),"") -> 3 | C34: =IF(RSA!$C$10,AND(A34<RSA!$C$16,B34=1),FALSE) -> FALSE | D34: =IF(C34,A34,"") | F34: 25 | G34: =IF(RSA!$C$10,1+F34*RSA!$C$17,"") -> 12001 | H34: =IF(RSA!$C$10,G34/RSA!$C$18,"") -> 1714.4286 | I34: =IF(RSA!$C$10,MOD(G34,RSA!$C$18),"") -> 3 | J34: =IF(RSA!$C$10,IF(AND(F34<RSA!$C$18,I34=0),H34,""),"")
A35: 28 | B35: =IF(RSA!$C$10,GCD(A35,RSA!$C$17),"") -> 4 | C35: =IF(RSA!$C$10,AND(A35<RSA!$C$16,B35=1),FALSE) -> FALSE | D35: =IF(C35,A35,"") | F35: 26 | G35: =IF(RSA!$C$10,1+F35*RSA!$C$17,"") -> 12481 | H35: =IF(RSA!$C$10,G35/RSA!$C$18,"") -> 1783 | I35: =IF(RSA!$C$10,MOD(G35,RSA!$C$18),"") -> 0 | J35: =IF(RSA!$C$10,IF(AND(F35<RSA!$C$18,I35=0),H35,""),"")
A36: 29 | B36: =IF(RSA!$C$10,GCD(A36,RSA!$C$17),"") -> 1 | C36: =IF(RSA!$C$10,AND(A36<RSA!$C$16,B36=1),FALSE) -> TRUE | D36: =IF(C36,A36,"") -> 29 | F36: 27 | G36: =IF(RSA!$C$10,1+F36*RSA!$C$17,"") -> 12961 | H36: =IF(RSA!$C$10,G36/RSA!$C$18,"") -> 1851.5714 | I36: =IF(RSA!$C$10,MOD(G36,RSA!$C$18),"") -> 4 | J36: =IF(RSA!$C$10,IF(AND(F36<RSA!$C$18,I36=0),H36,""),"")
A37: 30 | B37: =IF(RSA!$C$10,GCD(A37,RSA!$C$17),"") -> 30 | C37: =IF(RSA!$C$10,AND(A37<RSA!$C$16,B37=1),FALSE) -> FALSE | D37: =IF(C37,A37,"") | F37: 28 | G37: =IF(RSA!$C$10,1+F37*RSA!$C$17,"") -> 13441 | H37: =IF(RSA!$C$10,G37/RSA!$C$18,"") -> 1920.1429 | I37: =IF(RSA!$C$10,MOD(G37,RSA!$C$18),"") -> 1 | J37: =IF(RSA!$C$10,IF(AND(F37<RSA!$C$18,I37=0),H37,""),"")
A38: 31 | B38: =IF(RSA!$C$10,GCD(A38,RSA!$C$17),"") -> 1 | C38: =IF(RSA!$C$10,AND(A38<RSA!$C$16,B38=1),FALSE) -> TRUE | D38: =IF(C38,A38,"") -> 31 | F38: 29 | G38: =IF(RSA!$C$10,1+F38*RSA!$C$17,"") -> 13921 | H38: =IF(RSA!$C$10,G38/RSA!$C$18,"") -> 1988.7143 | I38: =IF(RSA!$C$10,MOD(G38,RSA!$C$18),"") -> 5 | J38: =IF(RSA!$C$10,IF(AND(F38<RSA!$C$18,I38=0),H38,""),"")
A39: 32 | B39: =IF(RSA!$C$10,GCD(A39,RSA!$C$17),"") -> 32 | C39: =IF(RSA!$C$10,AND(A39<RSA!$C$16,B39=1),FALSE) -> FALSE | D39: =IF(C39,A39,"") | F39: 30 | G39: =IF(RSA!$C$10,1+F39*RSA!$C$17,"") -> 14401 | H39: =IF(RSA!$C$10,G39/RSA!$C$18,"") -> 2057.2857 | I39: =IF(RSA!$C$10,MOD(G39,RSA!$C$18),"") -> 2 | J39: =IF(RSA!$C$10,IF(AND(F39<RSA!$C$18,I39=0),H39,""),"")
A40: 33 | B40: =IF(RSA!$C$10,GCD(A40,RSA!$C$17),"") -> 3 | C40: =IF(RSA!$C$10,AND(A40<RSA!$C$16,B40=1),FALSE) -> FALSE | D40: =IF(C40,A40,"") | F40: 31 | G40: =IF(RSA!$C$10,1+F40*RSA!$C$17,"") -> 14881 | H40: =IF(RSA!$C$10,G40/RSA!$C$18,"") -> 2125.8571 | I40: =IF(RSA!$C$10,MOD(G40,RSA!$C$18),"") -> 6 | J40: =IF(RSA!$C$10,IF(AND(F40<RSA!$C$18,I40=0),H40,""),"")
A41: 34 | B41: =IF(RSA!$C$10,GCD(A41,RSA!$C$17),"") -> 2 | C41: =IF(RSA!$C$10,AND(A41<RSA!$C$16,B41=1),FALSE) -> FALSE | D41: =IF(C41,A41,"") | F41: 32 | G41: =IF(RSA!$C$10,1+F41*RSA!$C$17,"") -> 15361 | H41: =IF(RSA!$C$10,G41/RSA!$C$18,"") -> 2194.4286 | I41: =IF(RSA!$C$10,MOD(G41,RSA!$C$18),"") -> 3 | J41: =IF(RSA!$C$10,IF(AND(F41<RSA!$C$18,I41=0),H41,""),"")
A42: 35 | B42: =IF(RSA!$C$10,GCD(A42,RSA!$C$17),"") -> 5 | C42: =IF(RSA!$C$10,AND(A42<RSA!$C$16,B42=1),FALSE) -> FALSE | D42: =IF(C42,A42,"") | F42: 33 | G42: =IF(RSA!$C$10,1+F42*RSA!$C$17,"") -> 15841 | H42: =IF(RSA!$C$10,G42/RSA!$C$18,"") -> 2263 | I42: =IF(RSA!$C$10,MOD(G42,RSA!$C$18),"") -> 0 | J42: =IF(RSA!$C$10,IF(AND(F42<RSA!$C$18,I42=0),H42,""),"")
A43: 36 | B43: =IF(RSA!$C$10,GCD(A43,RSA!$C$17),"") -> 12 | C43: =IF(RSA!$C$10,AND(A43<RSA!$C$16,B43=1),FALSE) -> FALSE | D43: =IF(C43,A43,"") | F43: 34 | G43: =IF(RSA!$C$10,1+F43*RSA!$C$17,"") -> 16321 | H43: =IF(RSA!$C$10,G43/RSA!$C$18,"") -> 2331.5714 | I43: =IF(RSA!$C$10,MOD(G43,RSA!$C$18),"") -> 4 | J43: =IF(RSA!$C$10,IF(AND(F43<RSA!$C$18,I43=0),H43,""),"")
A44: 37 | B44: =IF(RSA!$C$10,GCD(A44,RSA!$C$17),"") -> 1 | C44: =IF(RSA!$C$10,AND(A44<RSA!$C$16,B44=1),FALSE) -> TRUE | D44: =IF(C44,A44,"") -> 37 | F44: 35 | G44: =IF(RSA!$C$10,1+F44*RSA!$C$17,"") -> 16801 | H44: =IF(RSA!$C$10,G44/RSA!$C$18,"") -> 2400.1429 | I44: =IF(RSA!$C$10,MOD(G44,RSA!$C$18),"") -> 1 | J44: =IF(RSA!$C$10,IF(AND(F44<RSA!$C$18,I44=0),H44,""),"")
A45: 38 | B45: =IF(RSA!$C$10,GCD(A45,RSA!$C$17),"") -> 2 | C45: =IF(RSA!$C$10,AND(A45<RSA!$C$16,B45=1),FALSE) -> FALSE | D45: =IF(C45,A45,"") | F45: 36 | G45: =IF(RSA!$C$10,1+F45*RSA!$C$17,"") -> 17281 | H45: =IF(RSA!$C$10,G45/RSA!$C$18,"") -> 2468.7143 | I45: =IF(RSA!$C$10,MOD(G45,RSA!$C$18),"") -> 5 | J45: =IF(RSA!$C$10,IF(AND(F45<RSA!$C$18,I45=0),H45,""),"")
... A106: 99 | B106: =IF(RSA!$C$10,GCD(A106,RSA!$C$17),"") -> 3 | C106: =IF(RSA!$C$10,AND(A106<RSA!$C$16,B106=1),FALSE) -> FALSE | D106: =IF(C106,A106,"") | F106: 97 | G106: =IF(RSA!$C$10,1+F106*RSA!$C$17,"") -> 46561 | H106: =IF(RSA!$C$10,G106/RSA!$C$18,"") -> 6651.5714 | I106: =IF(RSA!$C$10,MOD(G106,RSA!$C$18),"") -> 4 | J106: =IF(RSA!$C$10,IF(AND(F106<RSA!$C$18,I106=0),H106,""),"")
F107: 98 | G107: =IF(RSA!$C$10,1+F107*RSA!$C$17,"") -> 47041 | H107: =IF(RSA!$C$10,G107/RSA!$C$18,"") -> 6720.1429 | I107: =IF(RSA!$C$10,MOD(G107,RSA!$C$18),"") -> 1 | J107: =IF(RSA!$C$10,IF(AND(F107<RSA!$C$18,I107=0),H107,""),"")

Sheet Power steps
A2: Modular powers without enormous numbers
A4: Read one character block from top to bottom. Left encrypts with e. Right decrypts with d.
A5: Start with result 1. If the exponent is odd, multiply the result by the base and take MOD(..., n).
A6: Then halve the exponent (round down), square the base modulo n, and repeat. At exponent 0 the result stays unchanged.
A7: 14 rows cover exponents below 16,384. All supported d values are smaller. The final result feeds the RSA tab.
A8: Character 1: encryption | I8: Character 1: decryption
A9: Step | B9: Exponent left | C9: Base mod n | D9: Odd? | E9: Result before | F9: Multiplier | G9: Result after | I9: Step | J9: Exponent left | K9: Base mod n | L9: Odd? | M9: Result before | N9: Multiplier | O9: Result after
A10: 1 | B10: =IF(OR(RSA!$C$12<>"Ready",LEN(RSA!C42)=0),"",RSA!$C$18) -> 7 | C10: =IF(OR(RSA!$C$12<>"Ready",LEN(RSA!C42)=0),"",RSA!D42) -> 72 | D10: =IF(OR(RSA!$C$12<>"Ready",LEN(RSA!C42)=0),"",MOD(B10,2)) -> 1 | E10: =IF(OR(RSA!$C$12<>"Ready",LEN(RSA!C42)=0),"",1) -> 1 | F10: =IF(OR(RSA!$C$12<>"Ready",LEN(RSA!C42)=0),"",IF(D10=1,C10,1)) -> 72 | G10: =IF(OR(RSA!$C$12<>"Ready",LEN(RSA!C42)=0),"",MOD(E10*F10,RSA!$C$16)) -> 72 | I10: 1 | J10: =IF(OR(RSA!$C$12<>"Ready",LEN(RSA!C42)=0),"",RSA!$C$19) -> 343 | K10: =IF(OR(RSA!$C$12<>"Ready",LEN(RSA!C42)=0),"",RSA!F42) -> 474 | L10: =IF(OR(RSA!$C$12<>"Ready",LEN(RSA!C42)=0),"",MOD(J10,2)) -> 1 | M10: =IF(OR(RSA!$C$12<>"Ready",LEN(RSA!C42)=0),"",1) -> 1 | N10: =IF(OR(RSA!$C$12<>"Ready",LEN(RSA!C42)=0),"",IF(L10=1,K10,1)) -> 474 | O10: =IF(OR(RSA!$C$12<>"Ready",LEN(RSA!C42)=0),"",MOD(M10*N10,RSA!$C$16)) -> 474
A11: 2 | B11: =IF(OR(RSA!$C$12<>"Ready",LEN(RSA!C42)=0),"",INT(B10/2)) -> 3 | C11: =IF(OR(RSA!$C$12<>"Ready",LEN(RSA!C42)=0),"",MOD(C10*C10,RSA!$C$16)) -> 387 | D11: =IF(OR(RSA!$C$12<>"Ready",LEN(RSA!C42)=0),"",MOD(B11,2)) -> 1 | E11: =IF(OR(RSA!$C$12<>"Ready",LEN(RSA!C42)=0),"",G10) -> 72 | F11: =IF(OR(RSA!$C$12<>"Ready",LEN(RSA!C42)=0),"",IF(D11=1,C11,1)) -> 387 | G11: =IF(OR(RSA!$C$12<>"Ready",LEN(RSA!C42)=0),"",MOD(E11*F11,RSA!$C$16)) -> 148 | I11: 2 | J11: =IF(OR(RSA!$C$12<>"Ready",LEN(RSA!C42)=0),"",INT(J10/2)) -> 171 | K11: =IF(OR(RSA!$C$12<>"Ready",LEN(RSA!C42)=0),"",MOD(K10*K10,RSA!$C$16)) -> 283 | L11: =IF(OR(RSA!$C$12<>"Ready",LEN(RSA!C42)=0),"",MOD(J11,2)) -> 1 | M11: =IF(OR(RSA!$C$12<>"Ready",LEN(RSA!C42)=0),"",O10) -> 474 | N11: =IF(OR(RSA!$C$12<>"Ready",LEN(RSA!C42)=0),"",IF(L11=1,K11,1)) -> 283 | O11: =IF(OR(RSA!$C$12<>"Ready",LEN(RSA!C42)=0),"",MOD(M11*N11,RSA!$C$16)) -> 359
A12: 3 | B12: =IF(OR(RSA!$C$12<>"Ready",LEN(RSA!C42)=0),"",INT(B11/2)) -> 1 | C12: =IF(OR(RSA!$C$12<>"Ready",LEN(RSA!C42)=0),"",MOD(C11*C11,RSA!$C$16)) -> 529 | D12: =IF(OR(RSA!$C$12<>"Ready",LEN(RSA!C42)=0),"",MOD(B12,2)) -> 1 | E12: =IF(OR(RSA!$C$12<>"Ready",LEN(RSA!C42)=0),"",G11) -> 148 | F12: =IF(OR(RSA!$C$12<>"Ready",LEN(RSA!C42)=0),"",IF(D12=1,C12,1)) -> 529 | G12: =IF(OR(RSA!$C$12<>"Ready",LEN(RSA!C42)=0),"",MOD(E12*F12,RSA!$C$16)) -> 474 | I12: 3 | J12: =IF(OR(RSA!$C$12<>"Ready",LEN(RSA!C42)=0),"",INT(J11/2)) -> 85 | K12: =IF(OR(RSA!$C$12<>"Ready",LEN(RSA!C42)=0),"",MOD(K11*K11,RSA!$C$16)) -> 139 | L12: =IF(OR(RSA!$C$12<>"Ready",LEN(RSA!C42)=0),"",MOD(J12,2)) -> 1 | M12: =IF(OR(RSA!$C$12<>"Ready",LEN(RSA!C42)=0),"",O11) -> 359 | N12: =IF(OR(RSA!$C$12<>"Ready",LEN(RSA!C42)=0),"",IF(L12=1,K12,1)) -> 139 | O12: =IF(OR(RSA!$C$12<>"Ready",LEN(RSA!C42)=0),"",MOD(M12*N12,RSA!$C$16)) -> 332
A13: 4 | B13: =IF(OR(RSA!$C$12<>"Ready",LEN(RSA!C42)=0),"",INT(B12/2)) -> 0 | C13: =IF(OR(RSA!$C$12<>"Ready",LEN(RSA!C42)=0),"",MOD(C12*C12,RSA!$C$16)) -> 16 | D13: =IF(OR(RSA!$C$12<>"Ready",LEN(RSA!C42)=0),"",MOD(B13,2)) -> 0 | E13: =IF(OR(RSA!$C$12<>"Ready",LEN(RSA!C42)=0),"",G12) -> 474 | F13: =IF(OR(RSA!$C$12<>"Ready",LEN(RSA!C42)=0),"",IF(D13=1,C13,1)) -> 1 | G13: =IF(OR(RSA!$C$12<>"Ready",LEN(RSA!C42)=0),"",MOD(E13*F13,RSA!$C$16)) -> 474 | I13: 4 | J13: =IF(OR(RSA!$C$12<>"Ready",LEN(RSA!C42)=0),"",INT(J12/2)) -> 42 | K13: =IF(OR(RSA!$C$12<>"Ready",LEN(RSA!C42)=0),"",MOD(K12*K12,RSA!$C$16)) -> 133 | L13: =IF(OR(RSA!$C$12<>"Ready",LEN(RSA!C42)=0),"",MOD(J13,2)) -> 0 | M13: =IF(OR(RSA!$C$12<>"Ready",LEN(RSA!C42)=0),"",O12) -> 332 | N13: =IF(OR(RSA!$C$12<>"Ready",LEN(RSA!C42)=0),"",IF(L13=1,K13,1)) -> 1 | O13: =IF(OR(RSA!$C$12<>"Ready",LEN(RSA!C42)=0),"",MOD(M13*N13,RSA!$C$16)) -> 332
A14: 5 | B14: =IF(OR(RSA!$C$12<>"Ready",LEN(RSA!C42)=0),"",INT(B13/2)) -> 0 | C14: =IF(OR(RSA!$C$12<>"Ready",LEN(RSA!C42)=0),"",MOD(C13*C13,RSA!$C$16)) -> 256 | D14: =IF(OR(RSA!$C$12<>"Ready",LEN(RSA!C42)=0),"",MOD(B14,2)) -> 0 | E14: =IF(OR(RSA!$C$12<>"Ready",LEN(RSA!C42)=0),"",G13) -> 474 | F14: =IF(OR(RSA!$C$12<>"Ready",LEN(RSA!C42)=0),"",IF(D14=1,C14,1)) -> 1 | G14: =IF(OR(RSA!$C$12<>"Ready",LEN(RSA!C42)=0),"",MOD(E14*F14,RSA!$C$16)) -> 474 | I14: 5 | J14: =IF(OR(RSA!$C$12<>"Ready",LEN(RSA!C42)=0),"",INT(J13/2)) -> 21 | K14: =IF(OR(RSA!$C$12<>"Ready",LEN(RSA!C42)=0),"",MOD(K13*K13,RSA!$C$16)) -> 100 | L14: =IF(OR(RSA!$C$12<>"Ready",LEN(RSA!C42)=0),"",MOD(J14,2)) -> 1 | M14: =IF(OR(RSA!$C$12<>"Ready",LEN(RSA!C42)=0),"",O13) -> 332 | N14: =IF(OR(RSA!$C$12<>"Ready",LEN(RSA!C42)=0),"",IF(L14=1,K14,1)) -> 100 | O14: =IF(OR(RSA!$C$12<>"Ready",LEN(RSA!C42)=0),"",MOD(M14*N14,RSA!$C$16)) -> 154
A15: 6 | B15: =IF(OR(RSA!$C$12<>"Ready",LEN(RSA!C42)=0),"",INT(B14/2)) -> 0 | C15: =IF(OR(RSA!$C$12<>"Ready",LEN(RSA!C42)=0),"",MOD(C14*C14,RSA!$C$16)) -> 510 | D15: =IF(OR(RSA!$C$12<>"Ready",LEN(RSA!C42)=0),"",MOD(B15,2)) -> 0 | E15: =IF(OR(RSA!$C$12<>"Ready",LEN(RSA!C42)=0),"",G14) -> 474 | F15: =IF(OR(RSA!$C$12<>"Ready",LEN(RSA!C42)=0),"",IF(D15=1,C15,1)) -> 1 | G15: =IF(OR(RSA!$C$12<>"Ready",LEN(RSA!C42)=0),"",MOD(E15*F15,RSA!$C$16)) -> 474 | I15: 6 | J15: =IF(OR(RSA!$C$12<>"Ready",LEN(RSA!C42)=0),"",INT(J14/2)) -> 10 | K15: =IF(OR(RSA!$C$12<>"Ready",LEN(RSA!C42)=0),"",MOD(K14*K14,RSA!$C$16)) -> 406 | L15: =IF(OR(RSA!$C$12<>"Ready",LEN(RSA!C42)=0),"",MOD(J15,2)) -> 0 | M15: =IF(OR(RSA!$C$12<>"Ready",LEN(RSA!C42)=0),"",O14) -> 154 | N15: =IF(OR(RSA!$C$12<>"Ready",LEN(RSA!C42)=0),"",IF(L15=1,K15,1)) -> 1 | O15: =IF(OR(RSA!$C$12<>"Ready",LEN(RSA!C42)=0),"",MOD(M15*N15,RSA!$C$16)) -> 154
A16: 7 | B16: =IF(OR(RSA!$C$12<>"Ready",LEN(RSA!C42)=0),"",INT(B15/2)) -> 0 | C16: =IF(OR(RSA!$C$12<>"Ready",LEN(RSA!C42)=0),"",MOD(C15*C15,RSA!$C$16)) -> 529 | D16: =IF(OR(RSA!$C$12<>"Ready",LEN(RSA!C42)=0),"",MOD(B16,2)) -> 0 | E16: =IF(OR(RSA!$C$12<>"Ready",LEN(RSA!C42)=0),"",G15) -> 474 | F16: =IF(OR(RSA!$C$12<>"Ready",LEN(RSA!C42)=0),"",IF(D16=1,C16,1)) -> 1 | G16: =IF(OR(RSA!$C$12<>"Ready",LEN(RSA!C42)=0),"",MOD(E16*F16,RSA!$C$16)) -> 474 | I16: 7 | J16: =IF(OR(RSA!$C$12<>"Ready",LEN(RSA!C42)=0),"",INT(J15/2)) -> 5 | K16: =IF(OR(RSA!$C$12<>"Ready",LEN(RSA!C42)=0),"",MOD(K15*K15,RSA!$C$16)) -> 139 | L16: =IF(OR(RSA!$C$12<>"Ready",LEN(RSA!C42)=0),"",MOD(J16,2)) -> 1 | M16: =IF(OR(RSA!$C$12<>"Ready",LEN(RSA!C42)=0),"",O15) -> 154 | N16: =IF(OR(RSA!$C$12<>"Ready",LEN(RSA!C42)=0),"",IF(L16=1,K16,1)) -> 139 | O16: =IF(OR(RSA!$C$12<>"Ready",LEN(RSA!C42)=0),"",MOD(M16*N16,RSA!$C$16)) -> 86
A17: 8 | B17: =IF(OR(RSA!$C$12<>"Ready",LEN(RSA!C42)=0),"",INT(B16/2)) -> 0 | C17: =IF(OR(RSA!$C$12<>"Ready",LEN(RSA!C42)=0),"",MOD(C16*C16,RSA!$C$16)) -> 16 | D17: =IF(OR(RSA!$C$12<>"Ready",LEN(RSA!C42)=0),"",MOD(B17,2)) -> 0 | E17: =IF(OR(RSA!$C$12<>"Ready",LEN(RSA!C42)=0),"",G16) -> 474 | F17: =IF(OR(RSA!$C$12<>"Ready",LEN(RSA!C42)=0),"",IF(D17=1,C17,1)) -> 1 | G17: =IF(OR(RSA!$C$12<>"Ready",LEN(RSA!C42)=0),"",MOD(E17*F17,RSA!$C$16)) -> 474 | I17: 8 | J17: =IF(OR(RSA!$C$12<>"Ready",LEN(RSA!C42)=0),"",INT(J16/2)) -> 2 | K17: =IF(OR(RSA!$C$12<>"Ready",LEN(RSA!C42)=0),"",MOD(K16*K16,RSA!$C$16)) -> 133 | L17: =IF(OR(RSA!$C$12<>"Ready",LEN(RSA!C42)=0),"",MOD(J17,2)) -> 0 | M17: =IF(OR(RSA!$C$12<>"Ready",LEN(RSA!C42)=0),"",O16) -> 86 | N17: =IF(OR(RSA!$C$12<>"Ready",LEN(RSA!C42)=0),"",IF(L17=1,K17,1)) -> 1 | O17: =IF(OR(RSA!$C$12<>"Ready",LEN(RSA!C42)=0),"",MOD(M17*N17,RSA!$C$16)) -> 86
A18: 9 | B18: =IF(OR(RSA!$C$12<>"Ready",LEN(RSA!C42)=0),"",INT(B17/2)) -> 0 | C18: =IF(OR(RSA!$C$12<>"Ready",LEN(RSA!C42)=0),"",MOD(C17*C17,RSA!$C$16)) -> 256 | D18: =IF(OR(RSA!$C$12<>"Ready",LEN(RSA!C42)=0),"",MOD(B18,2)) -> 0 | E18: =IF(OR(RSA!$C$12<>"Ready",LEN(RSA!C42)=0),"",G17) -> 474 | F18: =IF(OR(RSA!$C$12<>"Ready",LEN(RSA!C42)=0),"",IF(D18=1,C18,1)) -> 1 | G18: =IF(OR(RSA!$C$12<>"Ready",LEN(RSA!C42)=0),"",MOD(E18*F18,RSA!$C$16)) -> 474 | I18: 9 | J18: =IF(OR(RSA!$C$12<>"Ready",LEN(RSA!C42)=0),"",INT(J17/2)) -> 1 | K18: =IF(OR(RSA!$C$12<>"Ready",LEN(RSA!C42)=0),"",MOD(K17*K17,RSA!$C$16)) -> 100 | L18: =IF(OR(RSA!$C$12<>"Ready",LEN(RSA!C42)=0),"",MOD(J18,2)) -> 1 | M18: =IF(OR(RSA!$C$12<>"Ready",LEN(RSA!C42)=0),"",O17) -> 86 | N18: =IF(OR(RSA!$C$12<>"Ready",LEN(RSA!C42)=0),"",IF(L18=1,K18,1)) -> 100 | O18: =IF(OR(RSA!$C$12<>"Ready",LEN(RSA!C42)=0),"",MOD(M18*N18,RSA!$C$16)) -> 72
A19: 10 | B19: =IF(OR(RSA!$C$12<>"Ready",LEN(RSA!C42)=0),"",INT(B18/2)) -> 0 | C19: =IF(OR(RSA!$C$12<>"Ready",LEN(RSA!C42)=0),"",MOD(C18*C18,RSA!$C$16)) -> 510 | D19: =IF(OR(RSA!$C$12<>"Ready",LEN(RSA!C42)=0),"",MOD(B19,2)) -> 0 | E19: =IF(OR(RSA!$C$12<>"Ready",LEN(RSA!C42)=0),"",G18) -> 474 | F19: =IF(OR(RSA!$C$12<>"Ready",LEN(RSA!C42)=0),"",IF(D19=1,C19,1)) -> 1 | G19: =IF(OR(RSA!$C$12<>"Ready",LEN(RSA!C42)=0),"",MOD(E19*F19,RSA!$C$16)) -> 474 | I19: 10 | J19: =IF(OR(RSA!$C$12<>"Ready",LEN(RSA!C42)=0),"",INT(J18/2)) -> 0 | K19: =IF(OR(RSA!$C$12<>"Ready",LEN(RSA!C42)=0),"",MOD(K18*K18,RSA!$C$16)) -> 406 | L19: =IF(OR(RSA!$C$12<>"Ready",LEN(RSA!C42)=0),"",MOD(J19,2)) -> 0 | M19: =IF(OR(RSA!$C$12<>"Ready",LEN(RSA!C42)=0),"",O18) -> 72 | N19: =IF(OR(RSA!$C$12<>"Ready",LEN(RSA!C42)=0),"",IF(L19=1,K19,1)) -> 1 | O19: =IF(OR(RSA!$C$12<>"Ready",LEN(RSA!C42)=0),"",MOD(M19*N19,RSA!$C$16)) -> 72
A20: 11 | B20: =IF(OR(RSA!$C$12<>"Ready",LEN(RSA!C42)=0),"",INT(B19/2)) -> 0 | C20: =IF(OR(RSA!$C$12<>"Ready",LEN(RSA!C42)=0),"",MOD(C19*C19,RSA!$C$16)) -> 529 | D20: =IF(OR(RSA!$C$12<>"Ready",LEN(RSA!C42)=0),"",MOD(B20,2)) -> 0 | E20: =IF(OR(RSA!$C$12<>"Ready",LEN(RSA!C42)=0),"",G19) -> 474 | F20: =IF(OR(RSA!$C$12<>"Ready",LEN(RSA!C42)=0),"",IF(D20=1,C20,1)) -> 1 | G20: =IF(OR(RSA!$C$12<>"Ready",LEN(RSA!C42)=0),"",MOD(E20*F20,RSA!$C$16)) -> 474 | I20: 11 | J20: =IF(OR(RSA!$C$12<>"Ready",LEN(RSA!C42)=0),"",INT(J19/2)) -> 0 | K20: =IF(OR(RSA!$C$12<>"Ready",LEN(RSA!C42)=0),"",MOD(K19*K19,RSA!$C$16)) -> 139 | L20: =IF(OR(RSA!$C$12<>"Ready",LEN(RSA!C42)=0),"",MOD(J20,2)) -> 0 | M20: =IF(OR(RSA!$C$12<>"Ready",LEN(RSA!C42)=0),"",O19) -> 72 | N20: =IF(OR(RSA!$C$12<>"Ready",LEN(RSA!C42)=0),"",IF(L20=1,K20,1)) -> 1 | O20: =IF(OR(RSA!$C$12<>"Ready",LEN(RSA!C42)=0),"",MOD(M20*N20,RSA!$C$16)) -> 72
A21: 12 | B21: =IF(OR(RSA!$C$12<>"Ready",LEN(RSA!C42)=0),"",INT(B20/2)) -> 0 | C21: =IF(OR(RSA!$C$12<>"Ready",LEN(RSA!C42)=0),"",MOD(C20*C20,RSA!$C$16)) -> 16 | D21: =IF(OR(RSA!$C$12<>"Ready",LEN(RSA!C42)=0),"",MOD(B21,2)) -> 0 | E21: =IF(OR(RSA!$C$12<>"Ready",LEN(RSA!C42)=0),"",G20) -> 474 | F21: =IF(OR(RSA!$C$12<>"Ready",LEN(RSA!C42)=0),"",IF(D21=1,C21,1)) -> 1 | G21: =IF(OR(RSA!$C$12<>"Ready",LEN(RSA!C42)=0),"",MOD(E21*F21,RSA!$C$16)) -> 474 | I21: 12 | J21: =IF(OR(RSA!$C$12<>"Ready",LEN(RSA!C42)=0),"",INT(J20/2)) -> 0 | K21: =IF(OR(RSA!$C$12<>"Ready",LEN(RSA!C42)=0),"",MOD(K20*K20,RSA!$C$16)) -> 133 | L21: =IF(OR(RSA!$C$12<>"Ready",LEN(RSA!C42)=0),"",MOD(J21,2)) -> 0 | M21: =IF(OR(RSA!$C$12<>"Ready",LEN(RSA!C42)=0),"",O20) -> 72 | N21: =IF(OR(RSA!$C$12<>"Ready",LEN(RSA!C42)=0),"",IF(L21=1,K21,1)) -> 1 | O21: =IF(OR(RSA!$C$12<>"Ready",LEN(RSA!C42)=0),"",MOD(M21*N21,RSA!$C$16)) -> 72
A22: 13 | B22: =IF(OR(RSA!$C$12<>"Ready",LEN(RSA!C42)=0),"",INT(B21/2)) -> 0 | C22: =IF(OR(RSA!$C$12<>"Ready",LEN(RSA!C42)=0),"",MOD(C21*C21,RSA!$C$16)) -> 256 | D22: =IF(OR(RSA!$C$12<>"Ready",LEN(RSA!C42)=0),"",MOD(B22,2)) -> 0 | E22: =IF(OR(RSA!$C$12<>"Ready",LEN(RSA!C42)=0),"",G21) -> 474 | F22: =IF(OR(RSA!$C$12<>"Ready",LEN(RSA!C42)=0),"",IF(D22=1,C22,1)) -> 1 | G22: =IF(OR(RSA!$C$12<>"Ready",LEN(RSA!C42)=0),"",MOD(E22*F22,RSA!$C$16)) -> 474 | I22: 13 | J22: =IF(OR(RSA!$C$12<>"Ready",LEN(RSA!C42)=0),"",INT(J21/2)) -> 0 | K22: =IF(OR(RSA!$C$12<>"Ready",LEN(RSA!C42)=0),"",MOD(K21*K21,RSA!$C$16)) -> 100 | L22: =IF(OR(RSA!$C$12<>"Ready",LEN(RSA!C42)=0),"",MOD(J22,2)) -> 0 | M22: =IF(OR(RSA!$C$12<>"Ready",LEN(RSA!C42)=0),"",O21) -> 72 | N22: =IF(OR(RSA!$C$12<>"Ready",LEN(RSA!C42)=0),"",IF(L22=1,K22,1)) -> 1 | O22: =IF(OR(RSA!$C$12<>"Ready",LEN(RSA!C42)=0),"",MOD(M22*N22,RSA!$C$16)) -> 72
A23: 14 | B23: =IF(OR(RSA!$C$12<>"Ready",LEN(RSA!C42)=0),"",INT(B22/2)) -> 0 | C23: =IF(OR(RSA!$C$12<>"Ready",LEN(RSA!C42)=0),"",MOD(C22*C22,RSA!$C$16)) -> 510 | D23: =IF(OR(RSA!$C$12<>"Ready",LEN(RSA!C42)=0),"",MOD(B23,2)) -> 0 | E23: =IF(OR(RSA!$C$12<>"Ready",LEN(RSA!C42)=0),"",G22) -> 474 | F23: =IF(OR(RSA!$C$12<>"Ready",LEN(RSA!C42)=0),"",IF(D23=1,C23,1)) -> 1 | G23: =IF(OR(RSA!$C$12<>"Ready",LEN(RSA!C42)=0),"",MOD(E23*F23,RSA!$C$16)) -> 474 | I23: 14 | J23: =IF(OR(RSA!$C$12<>"Ready",LEN(RSA!C42)=0),"",INT(J22/2)) -> 0 | K23: =IF(OR(RSA!$C$12<>"Ready",LEN(RSA!C42)=0),"",MOD(K22*K22,RSA!$C$16)) -> 406 | L23: =IF(OR(RSA!$C$12<>"Ready",LEN(RSA!C42)=0),"",MOD(J23,2)) -> 0 | M23: =IF(OR(RSA!$C$12<>"Ready",LEN(RSA!C42)=0),"",O22) -> 72 | N23: =IF(OR(RSA!$C$12<>"Ready",LEN(RSA!C42)=0),"",IF(L23=1,K23,1)) -> 1 | O23: =IF(OR(RSA!$C$12<>"Ready",LEN(RSA!C42)=0),"",MOD(M23*N23,RSA!$C$16)) -> 72
A26: Character 2: encryption | I26: Character 2: decryption
A27: Step | B27: Exponent left | C27: Base mod n | D27: Odd? | E27: Result before | F27: Multiplier | G27: Result after | I27: Step | J27: Exponent left | K27: Base mod n | L27: Odd? | M27: Result before | N27: Multiplier | O27: Result after
A28: 1 | B28: =IF(OR(RSA!$C$12<>"Ready",LEN(RSA!C43)=0),"",RSA!$C$18) -> 7 | C28: =IF(OR(RSA!$C$12<>"Ready",LEN(RSA!C43)=0),"",RSA!D43) -> 101 | D28: =IF(OR(RSA!$C$12<>"Ready",LEN(RSA!C43)=0),"",MOD(B28,2)) -> 1 | E28: =IF(OR(RSA!$C$12<>"Ready",LEN(RSA!C43)=0),"",1) -> 1 | F28: =IF(OR(RSA!$C$12<>"Ready",LEN(RSA!C43)=0),"",IF(D28=1,C28,1)) -> 101 | G28: =IF(OR(RSA!$C$12<>"Ready",LEN(RSA!C43)=0),"",MOD(E28*F28,RSA!$C$16)) -> 101 | I28: 1 | J28: =IF(OR(RSA!$C$12<>"Ready",LEN(RSA!C43)=0),"",RSA!$C$19) -> 343 | K28: =IF(OR(RSA!$C$12<>"Ready",LEN(RSA!C43)=0),"",RSA!F43) -> 153 | L28: =IF(OR(RSA!$C$12<>"Ready",LEN(RSA!C43)=0),"",MOD(J28,2)) -> 1 | M28: =IF(OR(RSA!$C$12<>"Ready",LEN(RSA!C43)=0),"",1) -> 1 | N28: =IF(OR(RSA!$C$12<>"Ready",LEN(RSA!C43)=0),"",IF(L28=1,K28,1)) -> 153 | O28: =IF(OR(RSA!$C$12<>"Ready",LEN(RSA!C43)=0),"",MOD(M28*N28,RSA!$C$16)) -> 153
A29: 2 | B29: =IF(OR(RSA!$C$12<>"Ready",LEN(RSA!C43)=0),"",INT(B28/2)) -> 3 | C29: =IF(OR(RSA!$C$12<>"Ready",LEN(RSA!C43)=0),"",MOD(C28*C28,RSA!$C$16)) -> 74 | D29: =IF(OR(RSA!$C$12<>"Ready",LEN(RSA!C43)=0),"",MOD(B29,2)) -> 1 | E29: =IF(OR(RSA!$C$12<>"Ready",LEN(RSA!C43)=0),"",G28) -> 101 | F29: =IF(OR(RSA!$C$12<>"Ready",LEN(RSA!C43)=0),"",IF(D29=1,C29,1)) -> 74 | G29: =IF(OR(RSA!$C$12<>"Ready",LEN(RSA!C43)=0),"",MOD(E29*F29,RSA!$C$16)) -> 12 | I29: 2 | J29: =IF(OR(RSA!$C$12<>"Ready",LEN(RSA!C43)=0),"",INT(J28/2)) -> 171 | K29: =IF(OR(RSA!$C$12<>"Ready",LEN(RSA!C43)=0),"",MOD(K28*K28,RSA!$C$16)) -> 490 | L29: =IF(OR(RSA!$C$12<>"Ready",LEN(RSA!C43)=0),"",MOD(J29,2)) -> 1 | M29: =IF(OR(RSA!$C$12<>"Ready",LEN(RSA!C43)=0),"",O28) -> 153 | N29: =IF(OR(RSA!$C$12<>"Ready",LEN(RSA!C43)=0),"",IF(L29=1,K29,1)) -> 490 | O29: =IF(OR(RSA!$C$12<>"Ready",LEN(RSA!C43)=0),"",MOD(M29*N29,RSA!$C$16)) -> 350
A30: 3 | B30: =IF(OR(RSA!$C$12<>"Ready",LEN(RSA!C43)=0),"",INT(B29/2)) -> 1 | C30: =IF(OR(RSA!$C$12<>"Ready",LEN(RSA!C43)=0),"",MOD(C29*C29,RSA!$C$16)) -> 146 | D30: =IF(OR(RSA!$C$12<>"Ready",LEN(RSA!C43)=0),"",MOD(B30,2)) -> 1 | E30: =IF(OR(RSA!$C$12<>"Ready",LEN(RSA!C43)=0),"",G29) -> 12 | F30: =IF(OR(RSA!$C$12<>"Ready",LEN(RSA!C43)=0),"",IF(D30=1,C30,1)) -> 146 | G30: =IF(OR(RSA!$C$12<>"Ready",LEN(RSA!C43)=0),"",MOD(E30*F30,RSA!$C$16)) -> 153 | I30: 3 | J30: =IF(OR(RSA!$C$12<>"Ready",LEN(RSA!C43)=0),"",INT(J29/2)) -> 85 | K30: =IF(OR(RSA!$C$12<>"Ready",LEN(RSA!C43)=0),"",MOD(K29*K29,RSA!$C$16)) -> 250 | L30: =IF(OR(RSA!$C$12<>"Ready",LEN(RSA!C43)=0),"",MOD(J30,2)) -> 1 | M30: =IF(OR(RSA!$C$12<>"Ready",LEN(RSA!C43)=0),"",O29) -> 350 | N30: =IF(OR(RSA!$C$12<>"Ready",LEN(RSA!C43)=0),"",IF(L30=1,K30,1)) -> 250 | O30: =IF(OR(RSA!$C$12<>"Ready",LEN(RSA!C43)=0),"",MOD(M30*N30,RSA!$C$16)) -> 88
A31: 4 | B31: =IF(OR(RSA!$C$12<>"Ready",LEN(RSA!C43)=0),"",INT(B30/2)) -> 0 | C31: =IF(OR(RSA!$C$12<>"Ready",LEN(RSA!C43)=0),"",MOD(C30*C30,RSA!$C$16)) -> 529 | D31: =IF(OR(RSA!$C$12<>"Ready",LEN(RSA!C43)=0),"",MOD(B31,2)) -> 0 | E31: =IF(OR(RSA!$C$12<>"Ready",LEN(RSA!C43)=0),"",G30) -> 153 | F31: =IF(OR(RSA!$C$12<>"Ready",LEN(RSA!C43)=0),"",IF(D31=1,C31,1)) -> 1 | G31: =IF(OR(RSA!$C$12<>"Ready",LEN(RSA!C43)=0),"",MOD(E31*F31,RSA!$C$16)) -> 153 | I31: 4 | J31: =IF(OR(RSA!$C$12<>"Ready",LEN(RSA!C43)=0),"",INT(J30/2)) -> 42 | K31: =IF(OR(RSA!$C$12<>"Ready",LEN(RSA!C43)=0),"",MOD(K30*K30,RSA!$C$16)) -> 139 | L31: =IF(OR(RSA!$C$12<>"Ready",LEN(RSA!C43)=0),"",MOD(J31,2)) -> 0 | M31: =IF(OR(RSA!$C$12<>"Ready",LEN(RSA!C43)=0),"",O30) -> 88 | N31: =IF(OR(RSA!$C$12<>"Ready",LEN(RSA!C43)=0),"",IF(L31=1,K31,1)) -> 1 | O31: =IF(OR(RSA!$C$12<>"Ready",LEN(RSA!C43)=0),"",MOD(M31*N31,RSA!$C$16)) -> 88
A32: 5 | B32: =IF(OR(RSA!$C$12<>"Ready",LEN(RSA!C43)=0),"",INT(B31/2)) -> 0 | C32: =IF(OR(RSA!$C$12<>"Ready",LEN(RSA!C43)=0),"",MOD(C31*C31,RSA!$C$16)) -> 16 | D32: =IF(OR(RSA!$C$12<>"Ready",LEN(RSA!C43)=0),"",MOD(B32,2)) -> 0 | E32: =IF(OR(RSA!$C$12<>"Ready",LEN(RSA!C43)=0),"",G31) -> 153 | F32: =IF(OR(RSA!$C$12<>"Ready",LEN(RSA!C43)=0),"",IF(D32=1,C32,1)) -> 1 | G32: =IF(OR(RSA!$C$12<>"Ready",LEN(RSA!C43)=0),"",MOD(E32*F32,RSA!$C$16)) -> 153 | I32: 5 | J32: =IF(OR(RSA!$C$12<>"Ready",LEN(RSA!C43)=0),"",INT(J31/2)) -> 21 | K32: =IF(OR(RSA!$C$12<>"Ready",LEN(RSA!C43)=0),"",MOD(K31*K31,RSA!$C$16)) -> 133 | L32: =IF(OR(RSA!$C$12<>"Ready",LEN(RSA!C43)=0),"",MOD(J32,2)) -> 1 | M32: =IF(OR(RSA!$C$12<>"Ready",LEN(RSA!C43)=0),"",O31) -> 88 | N32: =IF(OR(RSA!$C$12<>"Ready",LEN(RSA!C43)=0),"",IF(L32=1,K32,1)) -> 133 | O32: =IF(OR(RSA!$C$12<>"Ready",LEN(RSA!C43)=0),"",MOD(M32*N32,RSA!$C$16)) -> 511
A33: 6 | B33: =IF(OR(RSA!$C$12<>"Ready",LEN(RSA!C43)=0),"",INT(B32/2)) -> 0 | C33: =IF(OR(RSA!$C$12<>"Ready",LEN(RSA!C43)=0),"",MOD(C32*C32,RSA!$C$16)) -> 256 | D33: =IF(OR(RSA!$C$12<>"Ready",LEN(RSA!C43)=0),"",MOD(B33,2)) -> 0 | E33: =IF(OR(RSA!$C$12<>"Ready",LEN(RSA!C43)=0),"",G32) -> 153 | F33: =IF(OR(RSA!$C$12<>"Ready",LEN(RSA!C43)=0),"",IF(D33=1,C33,1)) -> 1 | G33: =IF(OR(RSA!$C$12<>"Ready",LEN(RSA!C43)=0),"",MOD(E33*F33,RSA!$C$16)) -> 153 | I33: 6 | J33: =IF(OR(RSA!$C$12<>"Ready",LEN(RSA!C43)=0),"",INT(J32/2)) -> 10 | K33: =IF(OR(RSA!$C$12<>"Ready",LEN(RSA!C43)=0),"",MOD(K32*K32,RSA!$C$16)) -> 100 | L33: =IF(OR(RSA!$C$12<>"Ready",LEN(RSA!C43)=0),"",MOD(J33,2)) -> 0 | M33: =IF(OR(RSA!$C$12<>"Ready",LEN(RSA!C43)=0),"",O32) -> 511 | N33: =IF(OR(RSA!$C$12<>"Ready",LEN(RSA!C43)=0),"",IF(L33=1,K33,1)) -> 1 | O33: =IF(OR(RSA!$C$12<>"Ready",LEN(RSA!C43)=0),"",MOD(M33*N33,RSA!$C$16)) -> 511
A34: 7 | B34: =IF(OR(RSA!$C$12<>"Ready",LEN(RSA!C43)=0),"",INT(B33/2)) -> 0 | C34: =IF(OR(RSA!$C$12<>"Ready",LEN(RSA!C43)=0),"",MOD(C33*C33,RSA!$C$16)) -> 510 | D34: =IF(OR(RSA!$C$12<>"Ready",LEN(RSA!C43)=0),"",MOD(B34,2)) -> 0 | E34: =IF(OR(RSA!$C$12<>"Ready",LEN(RSA!C43)=0),"",G33) -> 153 | F34: =IF(OR(RSA!$C$12<>"Ready",LEN(RSA!C43)=0),"",IF(D34=1,C34,1)) -> 1 | G34: =IF(OR(RSA!$C$12<>"Ready",LEN(RSA!C43)=0),"",MOD(E34*F34,RSA!$C$16)) -> 153 | I34: 7 | J34: =IF(OR(RSA!$C$12<>"Ready",LEN(RSA!C43)=0),"",INT(J33/2)) -> 5 | K34: =IF(OR(RSA!$C$12<>"Ready",LEN(RSA!C43)=0),"",MOD(K33*K33,RSA!$C$16)) -> 406 | L34: =IF(OR(RSA!$C$12<>"Ready",LEN(RSA!C43)=0),"",MOD(J34,2)) -> 1 | M34: =IF(OR(RSA!$C$12<>"Ready",LEN(RSA!C43)=0),"",O33) -> 511 | N34: =IF(OR(RSA!$C$12<>"Ready",LEN(RSA!C43)=0),"",IF(L34=1,K34,1)) -> 406 | O34: =IF(OR(RSA!$C$12<>"Ready",LEN(RSA!C43)=0),"",MOD(M34*N34,RSA!$C$16)) -> 129
A35: 8 | B35: =IF(OR(RSA!$C$12<>"Ready",LEN(RSA!C43)=0),"",INT(B34/2)) -> 0 | C35: =IF(OR(RSA!$C$12<>"Ready",LEN(RSA!C43)=0),"",MOD(C34*C34,RSA!$C$16)) -> 529 | D35: =IF(OR(RSA!$C$12<>"Ready",LEN(RSA!C43)=0),"",MOD(B35,2)) -> 0 | E35: =IF(OR(RSA!$C$12<>"Ready",LEN(RSA!C43)=0),"",G34) -> 153 | F35: =IF(OR(RSA!$C$12<>"Ready",LEN(RSA!C43)=0),"",IF(D35=1,C35,1)) -> 1 | G35: =IF(OR(RSA!$C$12<>"Ready",LEN(RSA!C43)=0),"",MOD(E35*F35,RSA!$C$16)) -> 153 | I35: 8 | J35: =IF(OR(RSA!$C$12<>"Ready",LEN(RSA!C43)=0),"",INT(J34/2)) -> 2 | K35: =IF(OR(RSA!$C$12<>"Ready",LEN(RSA!C43)=0),"",MOD(K34*K34,RSA!$C$16)) -> 139 | L35: =IF(OR(RSA!$C$12<>"Ready",LEN(RSA!C43)=0),"",MOD(J35,2)) -> 0 | M35: =IF(OR(RSA!$C$12<>"Ready",LEN(RSA!C43)=0),"",O34) -> 129 | N35: =IF(OR(RSA!$C$12<>"Ready",LEN(RSA!C43)=0),"",IF(L35=1,K35,1)) -> 1 | O35: =IF(OR(RSA!$C$12<>"Ready",LEN(RSA!C43)=0),"",MOD(M35*N35,RSA!$C$16)) -> 129
A36: 9 | B36: =IF(OR(RSA!$C$12<>"Ready",LEN(RSA!C43)=0),"",INT(B35/2)) -> 0 | C36: =IF(OR(RSA!$C$12<>"Ready",LEN(RSA!C43)=0),"",MOD(C35*C35,RSA!$C$16)) -> 16 | D36: =IF(OR(RSA!$C$12<>"Ready",LEN(RSA!C43)=0),"",MOD(B36,2)) -> 0 | E36: =IF(OR(RSA!$C$12<>"Ready",LEN(RSA!C43)=0),"",G35) -> 153 | F36: =IF(OR(RSA!$C$12<>"Ready",LEN(RSA!C43)=0),"",IF(D36=1,C36,1)) -> 1 | G36: =IF(OR(RSA!$C$12<>"Ready",LEN(RSA!C43)=0),"",MOD(E36*F36,RSA!$C$16)) -> 153 | I36: 9 | J36: =IF(OR(RSA!$C$12<>"Ready",LEN(RSA!C43)=0),"",INT(J35/2)) -> 1 | K36: =IF(OR(RSA!$C$12<>"Ready",LEN(RSA!C43)=0),"",MOD(K35*K35,RSA!$C$16)) -> 133 | L36: =IF(OR(RSA!$C$12<>"Ready",LEN(RSA!C43)=0),"",MOD(J36,2)) -> 1 | M36: =IF(OR(RSA!$C$12<>"Ready",LEN(RSA!C43)=0),"",O35) -> 129 | N36: =IF(OR(RSA!$C$12<>"Ready",LEN(RSA!C43)=0),"",IF(L36=1,K36,1)) -> 133 | O36: =IF(OR(RSA!$C$12<>"Ready",LEN(RSA!C43)=0),"",MOD(M36*N36,RSA!$C$16)) -> 101
A37: 10 | B37: =IF(OR(RSA!$C$12<>"Ready",LEN(RSA!C43)=0),"",INT(B36/2)) -> 0 | C37: =IF(OR(RSA!$C$12<>"Ready",LEN(RSA!C43)=0),"",MOD(C36*C36,RSA!$C$16)) -> 256 | D37: =IF(OR(RSA!$C$12<>"Ready",LEN(RSA!C43)=0),"",MOD(B37,2)) -> 0 | E37: =IF(OR(RSA!$C$12<>"Ready",LEN(RSA!C43)=0),"",G36) -> 153 | F37: =IF(OR(RSA!$C$12<>"Ready",LEN(RSA!C43)=0),"",IF(D37=1,C37,1)) -> 1 | G37: =IF(OR(RSA!$C$12<>"Ready",LEN(RSA!C43)=0),"",MOD(E37*F37,RSA!$C$16)) -> 153 | I37: 10 | J37: =IF(OR(RSA!$C$12<>"Ready",LEN(RSA!C43)=0),"",INT(J36/2)) -> 0 | K37: =IF(OR(RSA!$C$12<>"Ready",LEN(RSA!C43)=0),"",MOD(K36*K36,RSA!$C$16)) -> 100 | L37: =IF(OR(RSA!$C$12<>"Ready",LEN(RSA!C43)=0),"",MOD(J37,2)) -> 0 | M37: =IF(OR(RSA!$C$12<>"Ready",LEN(RSA!C43)=0),"",O36) -> 101 | N37: =IF(OR(RSA!$C$12<>"Ready",LEN(RSA!C43)=0),"",IF(L37=1,K37,1)) -> 1 | O37: =IF(OR(RSA!$C$12<>"Ready",LEN(RSA!C43)=0),"",MOD(M37*N37,RSA!$C$16)) -> 101
A38: 11 | B38: =IF(OR(RSA!$C$12<>"Ready",LEN(RSA!C43)=0),"",INT(B37/2)) -> 0 | C38: =IF(OR(RSA!$C$12<>"Ready",LEN(RSA!C43)=0),"",MOD(C37*C37,RSA!$C$16)) -> 510 | D38: =IF(OR(RSA!$C$12<>"Ready",LEN(RSA!C43)=0),"",MOD(B38,2)) -> 0 | E38: =IF(OR(RSA!$C$12<>"Ready",LEN(RSA!C43)=0),"",G37) -> 153 | F38: =IF(OR(RSA!$C$12<>"Ready",LEN(RSA!C43)=0),"",IF(D38=1,C38,1)) -> 1 | G38: =IF(OR(RSA!$C$12<>"Ready",LEN(RSA!C43)=0),"",MOD(E38*F38,RSA!$C$16)) -> 153 | I38: 11 | J38: =IF(OR(RSA!$C$12<>"Ready",LEN(RSA!C43)=0),"",INT(J37/2)) -> 0 | K38: =IF(OR(RSA!$C$12<>"Ready",LEN(RSA!C43)=0),"",MOD(K37*K37,RSA!$C$16)) -> 406 | L38: =IF(OR(RSA!$C$12<>"Ready",LEN(RSA!C43)=0),"",MOD(J38,2)) -> 0 | M38: =IF(OR(RSA!$C$12<>"Ready",LEN(RSA!C43)=0),"",O37) -> 101 | N38: =IF(OR(RSA!$C$12<>"Ready",LEN(RSA!C43)=0),"",IF(L38=1,K38,1)) -> 1 | O38: =IF(OR(RSA!$C$12<>"Ready",LEN(RSA!C43)=0),"",MOD(M38*N38,RSA!$C$16)) -> 101
A39: 12 | B39: =IF(OR(RSA!$C$12<>"Ready",LEN(RSA!C43)=0),"",INT(B38/2)) -> 0 | C39: =IF(OR(RSA!$C$12<>"Ready",LEN(RSA!C43)=0),"",MOD(C38*C38,RSA!$C$16)) -> 529 | D39: =IF(OR(RSA!$C$12<>"Ready",LEN(RSA!C43)=0),"",MOD(B39,2)) -> 0 | E39: =IF(OR(RSA!$C$12<>"Ready",LEN(RSA!C43)=0),"",G38) -> 153 | F39: =IF(OR(RSA!$C$12<>"Ready",LEN(RSA!C43)=0),"",IF(D39=1,C39,1)) -> 1 | G39: =IF(OR(RSA!$C$12<>"Ready",LEN(RSA!C43)=0),"",MOD(E39*F39,RSA!$C$16)) -> 153 | I39: 12 | J39: =IF(OR(RSA!$C$12<>"Ready",LEN(RSA!C43)=0),"",INT(J38/2)) -> 0 | K39: =IF(OR(RSA!$C$12<>"Ready",LEN(RSA!C43)=0),"",MOD(K38*K38,RSA!$C$16)) -> 139 | L39: =IF(OR(RSA!$C$12<>"Ready",LEN(RSA!C43)=0),"",MOD(J39,2)) -> 0 | M39: =IF(OR(RSA!$C$12<>"Ready",LEN(RSA!C43)=0),"",O38) -> 101 | N39: =IF(OR(RSA!$C$12<>"Ready",LEN(RSA!C43)=0),"",IF(L39=1,K39,1)) -> 1 | O39: =IF(OR(RSA!$C$12<>"Ready",LEN(RSA!C43)=0),"",MOD(M39*N39,RSA!$C$16)) -> 101
A40: 13 | B40: =IF(OR(RSA!$C$12<>"Ready",LEN(RSA!C43)=0),"",INT(B39/2)) -> 0 | C40: =IF(OR(RSA!$C$12<>"Ready",LEN(RSA!C43)=0),"",MOD(C39*C39,RSA!$C$16)) -> 16 | D40: =IF(OR(RSA!$C$12<>"Ready",LEN(RSA!C43)=0),"",MOD(B40,2)) -> 0 | E40: =IF(OR(RSA!$C$12<>"Ready",LEN(RSA!C43)=0),"",G39) -> 153 | F40: =IF(OR(RSA!$C$12<>"Ready",LEN(RSA!C43)=0),"",IF(D40=1,C40,1)) -> 1 | G40: =IF(OR(RSA!$C$12<>"Ready",LEN(RSA!C43)=0),"",MOD(E40*F40,RSA!$C$16)) -> 153 | I40: 13 | J40: =IF(OR(RSA!$C$12<>"Ready",LEN(RSA!C43)=0),"",INT(J39/2)) -> 0 | K40: =IF(OR(RSA!$C$12<>"Ready",LEN(RSA!C43)=0),"",MOD(K39*K39,RSA!$C$16)) -> 133 | L40: =IF(OR(RSA!$C$12<>"Ready",LEN(RSA!C43)=0),"",MOD(J40,2)) -> 0 | M40: =IF(OR(RSA!$C$12<>"Ready",LEN(RSA!C43)=0),"",O39) -> 101 | N40: =IF(OR(RSA!$C$12<>"Ready",LEN(RSA!C43)=0),"",IF(L40=1,K40,1)) -> 1 | O40: =IF(OR(RSA!$C$12<>"Ready",LEN(RSA!C43)=0),"",MOD(M40*N40,RSA!$C$16)) -> 101
A41: 14 | B41: =IF(OR(RSA!$C$12<>"Ready",LEN(RSA!C43)=0),"",INT(B40/2)) -> 0 | C41: =IF(OR(RSA!$C$12<>"Ready",LEN(RSA!C43)=0),"",MOD(C40*C40,RSA!$C$16)) -> 256 | D41: =IF(OR(RSA!$C$12<>"Ready",LEN(RSA!C43)=0),"",MOD(B41,2)) -> 0 | E41: =IF(OR(RSA!$C$12<>"Ready",LEN(RSA!C43)=0),"",G40) -> 153 | F41: =IF(OR(RSA!$C$12<>"Ready",LEN(RSA!C43)=0),"",IF(D41=1,C41,1)) -> 1 | G41: =IF(OR(RSA!$C$12<>"Ready",LEN(RSA!C43)=0),"",MOD(E41*F41,RSA!$C$16)) -> 153 | I41: 14 | J41: =IF(OR(RSA!$C$12<>"Ready",LEN(RSA!C43)=0),"",INT(J40/2)) -> 0 | K41: =IF(OR(RSA!$C$12<>"Ready",LEN(RSA!C43)=0),"",MOD(K40*K40,RSA!$C$16)) -> 100 | L41: =IF(OR(RSA!$C$12<>"Ready",LEN(RSA!C43)=0),"",MOD(J41,2)) -> 0 | M41: =IF(OR(RSA!$C$12<>"Ready",LEN(RSA!C43)=0),"",O40) -> 101 | N41: =IF(OR(RSA!$C$12<>"Ready",LEN(RSA!C43)=0),"",IF(L41=1,K41,1)) -> 1 | O41: =IF(OR(RSA!$C$12<>"Ready",LEN(RSA!C43)=0),"",MOD(M41*N41,RSA!$C$16)) -> 101
A44: Character 3: encryption | I44: Character 3: decryption
A45: Step | B45: Exponent left | C45: Base mod n | D45: Odd? | E45: Result before | F45: Multiplier | G45: Result after | I45: Step | J45: Exponent left | K45: Base mod n | L45: Odd? | M45: Result before | N45: Multiplier | O45: Result after
A46: 1 | B46: =IF(OR(RSA!$C$12<>"Ready",LEN(RSA!C44)=0),"",RSA!$C$18) -> 7 | C46: =IF(OR(RSA!$C$12<>"Ready",LEN(RSA!C44)=0),"",RSA!D44) -> 108 | D46: =IF(OR(RSA!$C$12<>"Ready",LEN(RSA!C44)=0),"",MOD(B46,2)) -> 1 | E46: =IF(OR(RSA!$C$12<>"Ready",LEN(RSA!C44)=0),"",1) -> 1 | F46: =IF(OR(RSA!$C$12<>"Ready",LEN(RSA!C44)=0),"",IF(D46=1,C46,1)) -> 108 | G46: =IF(OR(RSA!$C$12<>"Ready",LEN(RSA!C44)=0),"",MOD(E46*F46,RSA!$C$16)) -> 108 | I46: 1 | J46: =IF(OR(RSA!$C$12<>"Ready",LEN(RSA!C44)=0),"",RSA!$C$19) -> 343 | K46: =IF(OR(RSA!$C$12<>"Ready",LEN(RSA!C44)=0),"",RSA!F44) -> 212 | L46: =IF(OR(RSA!$C$12<>"Ready",LEN(RSA!C44)=0),"",MOD(J46,2)) -> 1 | M46: =IF(OR(RSA!$C$12<>"Ready",LEN(RSA!C44)=0),"",1) -> 1 | N46: =IF(OR(RSA!$C$12<>"Ready",LEN(RSA!C44)=0),"",IF(L46=1,K46,1)) -> 212 | O46: =IF(OR(RSA!$C$12<>"Ready",LEN(RSA!C44)=0),"",MOD(M46*N46,RSA!$C$16)) -> 212
...

Sheet Power Steps explained
